Workbook
Name Slicer_Trimestre: #N/A
Name Slicer_Categoria: #N/A
Name Slicer_Producto: #N/A

Sheet Dashboard Final
B2: Ventas y márgenes 2026 · Dashboard ejecutivo
B3: =" "&Calculos!N59 -> En el período seleccionado el margen alcanza el 111% de la meta y representa el 30,0% de las ventas netas.
B5: VENTAS NETAS | F5: MARGEN % | J5: CUMPLIMIENTO DE META DE MARGEN | N5: CRECIMIENTO 2º SEM. VS 1º SEM.
B6: =Calculos!N5 -> 9.2459013e+09 | F6: =Calculos!N48 -> 0.29963288 | J6: =Calculos!N49 -> 1.1139871 | N6: =Calculos!N50 -> 0.01952655
B7: ="Ticket promedio $ "&FIXED(Calculos!N51,0)&" · "&FIXED(Calculos!N9,0)&" ventas" -> Ticket promedio $ 420.287 · 21.999 ventas | F7: ="Margen $ "&FIXED(Calculos!N7/1000000,0)&" M · meta implícita "&FIXED(IF(Calculos!N5>0,Calculos!N8/Calculos!N5,0)*100,1)&"%" -> Margen $ 2.770 M · meta implícita 26,9% | J7: ="Meta $ "&FIXED(Calculos!N8/1000000,0)&" M · verde = meta alcanzada" -> Meta $ 2.487 M · verde = meta alcanzada | N7: ="Sin año anterior: no hay YoY" -> Sin año anterior: no hay YoY
J35: Notas de análisis (revisadas con ChatGPT)
J36: 1. El margen estimado alcanza el 111 % de la meta, con menor cumplimiento relativo en Tecnología (69 %) y Línea Blanca (97 %). 2. Tecnología concentra el mayor volumen de ventas, pero presenta el menor margen estimado: 24 % de sus ventas y también el menor margen en pesos ($ 569 M). 3. La facturación de T4 supera en 2,8 % a la de T1 y las ventas mensuales se mueven entre $ 699 M (febrero) y $ 802 M (julio). 4. Los meses de menor cumplimiento (enero, mayo y julio) coinciden con metas más elevadas; falta determinar si la causa es la meta o el desempeño comercial. Atención: es un modelo de estimación. Los márgenes dependen de los % de costo supuestos por categoría y los importes son nominales, sin ajustar por inflación. Para confirmar estas conclusiones se necesitan costos reales por producto. Detalle en la hoja Analisis_IA.
B55: Fuente: transacciones 2026 limpias con Power Query (21.999). Costos estimados con un % fijo por categoría (supuesto). Metas: hoja Fact_Objetivos, interpretadas como meta de margen. Importes en pesos nominales, sin ajustar por inflación.

Sheet Calculos
B2: Hoja de soporte del Dashboard: tablas dinámicas (todas del mismo origen) y fórmulas IMPORTARDATOSDINAMICOS. | M2: Totales (responden a los segmentadores)
M3: Ventas Brutas | N3: =GETPIVOTDATA("Ventas Brutas",Calculos!$B$4) -> 9830501443
B4: Trimestre | C4: Ventas Brutas | D4: Descuentos | E4: Ventas Netas | F4: Costo Estimado | G4: Margen | H4: Meta de Margen | I4: Transacciones | J4: Unidades | M4: Descuentos | N4: =GETPIVOTDATA("Descuentos",Calculos!$B$4) -> 5.846001e+08
B5: T1 | C5: 2413730050 | D5: 1.427792e+08 | E5: 2.2709508e+09 | F5: 1.5902484e+09 | G5: 6.807024e+08 | H5: 5.7333573e+08 | I5: 5384 | J5: 35204 | M5: Ventas Netas | N5: =GETPIVOTDATA("Ventas Netas",Calculos!$B$4) -> 9.2459013e+09
B6: T2 | C6: 2451571774 | D6: 1.4427068e+08 | E6: 2.3073011e+09 | F6: 1.617588e+09 | G6: 6.8971308e+08 | H6: 6.8872483e+08 | I6: 5464 | J6: 34802 | M6: Costo Estimado | N6: =GETPIVOTDATA("Costo Estimado",Calculos!$B$4) -> 6.4755253e+09
B7: T3 | C7: 2487274001 | D7: 1.5239293e+08 | E7: 2.3348811e+09 | F7: 1.6367854e+09 | G7: 6.9809566e+08 | H7: 6.6870426e+08 | I7: 5556 | J7: 36153 | M7: Margen | N7: =GETPIVOTDATA("Margen",Calculos!$B$4) -> 2.7703761e+09
B8: T4 | C8: 2477925618 | D8: 1.4515729e+08 | E8: 2.3327683e+09 | F8: 1.6309034e+09 | G8: 7.0186494e+08 | H8: 5.5613658e+08 | I8: 5595 | J8: 36381 | M8: Meta de Margen | N8: =GETPIVOTDATA("Meta de Margen",Calculos!$B$4) -> 2.4869014e+09
B9: Total general | C9: 9830501443 | D9: 5.846001e+08 | E9: 9.2459013e+09 | F9: 6.4755253e+09 | G9: 2.7703761e+09 | H9: 2.4869014e+09 | I9: 21999 | J9: 142540 | M9: Transacciones | N9: =GETPIVOTDATA("Transacciones",Calculos!$B$4) -> 21999
M10: Unidades | N10: =GETPIVOTDATA("Unidades",Calculos!$B$4) -> 142540
M12: T1 | N12: =IFERROR(GETPIVOTDATA("Ventas Netas",Calculos!$B$4,"Trimestre","T1"),0) -> 2.2709508e+09
M13: T2 | N13: =IFERROR(GETPIVOTDATA("Ventas Netas",Calculos!$B$4,"Trimestre","T2"),0) -> 2.3073011e+09
M14: T3 | N14: =IFERROR(GETPIVOTDATA("Ventas Netas",Calculos!$B$4,"Trimestre","T3"),0) -> 2.3348811e+09
B15: Mes | C15: Ventas Netas | E15: Categoría | F15: Margen | G15: Meta de Margen | M15: T4 | N15: =IFERROR(GETPIVOTDATA("Ventas Netas",Calculos!$B$4,"Trimestre","T4"),0) -> 2.3327683e+09
B16: 01-Ene | C16: 7.8856096e+08 | E16: Electrónica | F16: 6.8860365e+08 | G16: 4.4048792e+08
B17: 02-Feb | C17: 6.9911065e+08 | E17: Hogar | F17: 8.756871e+08 | G17: 5.6357333e+08
B18: 03-Mar | C18: 7.8327923e+08 | E18: Línea Blanca | F18: 6.3712228e+08 | G18: 6.5716378e+08 | M18: 01-Ene | N18: =IFERROR(GETPIVOTDATA("Ventas Netas",Calculos!$B$15,"Mes","01-Ene"),0) -> 7.8856096e+08
B19: 04-Abr | C19: 7.6942399e+08 | E19: Tecnología | F19: 5.6896306e+08 | G19: 8.2567636e+08 | M19: 02-Feb | N19: =IFERROR(GETPIVOTDATA("Ventas Netas",Calculos!$B$15,"Mes","02-Feb"),0) -> 6.9911065e+08
B20: 05-May | C20: 7.4955159e+08 | E20: Total general | F20: 2.7703761e+09 | G20: 2.4869014e+09 | M20: 03-Mar | N20: =IFERROR(GETPIVOTDATA("Ventas Netas",Calculos!$B$15,"Mes","03-Mar"),0) -> 7.8327923e+08
B21: 06-Jun | C21: 7.8832552e+08 | M21: 04-Abr | N21: =IFERROR(GETPIVOTDATA("Ventas Netas",Calculos!$B$15,"Mes","04-Abr"),0) -> 7.6942399e+08
B22: 07-Jul | C22: 8.0220012e+08 | M22: 05-May | N22: =IFERROR(GETPIVOTDATA("Ventas Netas",Calculos!$B$15,"Mes","05-May"),0) -> 7.4955159e+08
B23: 08-Ago | C23: 7.7493472e+08 | M23: 06-Jun | N23: =IFERROR(GETPIVOTDATA("Ventas Netas",Calculos!$B$15,"Mes","06-Jun"),0) -> 7.8832552e+08
B24: 09-Sep | C24: 7.5774623e+08 | M24: 07-Jul | N24: =IFERROR(GETPIVOTDATA("Ventas Netas",Calculos!$B$15,"Mes","07-Jul"),0) -> 8.0220012e+08
B25: 10-Oct | C25: 7.8820764e+08 | M25: 08-Ago | N25: =IFERROR(GETPIVOTDATA("Ventas Netas",Calculos!$B$15,"Mes","08-Ago"),0) -> 7.7493472e+08
B26: 11-Nov | C26: 7.6736919e+08 | M26: 09-Sep | N26: =IFERROR(GETPIVOTDATA("Ventas Netas",Calculos!$B$15,"Mes","09-Sep"),0) -> 7.5774623e+08
B27: 12-Dic | C27: 7.771915e+08 | M27: 10-Oct | N27: =IFERROR(GETPIVOTDATA("Ventas Netas",Calculos!$B$15,"Mes","10-Oct"),0) -> 7.8820764e+08
B28: Total general | C28: 9.2459013e+09 | M28: 11-Nov | N28: =IFERROR(GETPIVOTDATA("Ventas Netas",Calculos!$B$15,"Mes","11-Nov"),0) -> 7.6736919e+08
M29: 12-Dic | N29: =IFERROR(GETPIVOTDATA("Ventas Netas",Calculos!$B$15,"Mes","12-Dic"),0) -> 7.771915e+08
M31: Categoría | N31: Margen | O31: Meta | P31: Cumplimiento
M32: Electrónica | N32: =IFERROR(GETPIVOTDATA("Margen",Calculos!$E$15,"Categoria","Electrónica"),0) -> 6.8860365e+08 | O32: =IFERROR(GETPIVOTDATA("Meta de Margen",Calculos!$E$15,"Categoria","Electrónica"),0) -> 4.4048792e+08 | P32: =IF(O32>0,N32/O32,"") -> 1.5632748
M33: Hogar | N33: =IFERROR(GETPIVOTDATA("Margen",Calculos!$E$15,"Categoria","Hogar"),0) -> 8.756871e+08 | O33: =IFERROR(GETPIVOTDATA("Meta de Margen",Calculos!$E$15,"Categoria","Hogar"),0) -> 5.6357333e+08 | P33: =IF(O33>0,N33/O33,"") -> 1.5538122
M34: Línea Blanca | N34: =IFERROR(GETPIVOTDATA("Margen",Calculos!$E$15,"Categoria","Línea Blanca"),0) -> 6.3712228e+08 | O34: =IFERROR(GETPIVOTDATA("Meta de Margen",Calculos!$E$15,"Categoria","Línea Blanca"),0) -> 6.5716378e+08 | P34: =IF(O34>0,N34/O34,"") -> 0.96950303
M35: Tecnología | N35: =IFERROR(GETPIVOTDATA("Margen",Calculos!$E$15,"Categoria","Tecnología"),0) -> 5.6896306e+08 | O35: =IFERROR(GETPIVOTDATA("Meta de Margen",Calculos!$E$15,"Categoria","Tecnología"),0) -> 8.2567636e+08 | P35: =IF(O35>0,N35/O35,"") -> 0.68908725
M40: Concepto | N40: Base | O40: Total | P40: Disminución | Q40: Margen
M41: Ventas brutas | N41: =0 -> 0 | O41: =N3 -> 9830501443 | P41: =0 -> 0 | Q41: =0 -> 0
M42: Descuentos | N42: =N5 -> 9.2459013e+09 | O42: =0 -> 0 | P42: =N4 -> 5.846001e+08 | Q42: =0 -> 0
M43: Ventas netas | N43: =0 -> 0 | O43: =N5 -> 9.2459013e+09 | P43: =0 -> 0 | Q43: =0 -> 0
M44: Costo estimado | N44: =N7 -> 2.7703761e+09 | O44: =0 -> 0 | P44: =N6 -> 6.4755253e+09 | Q44: =0 -> 0
M45: Margen | N45: =0 -> 0 | O45: =0 -> 0 | P45: =0 -> 0 | Q45: =N7 -> 2.7703761e+09
M47: KPIs
M48: Margen % | N48: =IF(N5>0,N7/N5,0) -> 0.29963288
...

Sheet Datos
A1: Fecha | B1: ID_Transaccion | C1: SKU | D1: Producto | E1: Categoria | F1: Mes | G1: Trimestre | H1: Cantidad | I1: Importe_Bruto | J1: Descuento_Importe | K1: Importe_Neto | L1: Costo_Estimado | M1: Importe_Margen | N1: Meta_Margen_Asignada
A2: 46023 | B2: TX-100608 | C2: ELEC-02 | D2: Microondas 20L | E2: Electrónica | F2: 01-Ene | G2: T1 | H2: 1 | I2: 355997 | J2: 21359.82 | K2: 334637.18 | L2: 234246.03 | M2: 100391.15 | N2: 57412.8
A3: 46023 | B3: TX-101399 | C3: ELEC-02 | D3: Microondas 20L | E3: Electrónica | F3: 01-Ene | G3: T1 | H3: 5 | I3: 298580 | J3: 0 | K3: 298580 | L3: 209006 | M3: 89574 | N3: 57412.8
A4: 46023 | B4: TX-101450 | C4: TECN-01 | D4: Celular Smartphone | E4: Tecnología | F4: 01-Ene | G4: T1 | H4: 7 | I4: 622047 | J4: 43543.29 | K4: 578503.71 | L4: 439662.82 | M4: 138840.89 | N4: 149162.21
A5: 46023 | B5: TX-101937 | C5: ELEC-01 | D5: TV Smart 55 | E5: Electrónica | F5: 01-Ene | G5: T1 | H5: 8 | I5: 508726 | J5: 40698.08 | K5: 468027.92 | L5: 327619.54 | M5: 140408.38 | N5: 57412.8
A6: 46023 | B6: TX-102132 | C6: HOGA-01 | D6: Cafetera Express | E6: Hogar | F6: 01-Ene | G6: T1 | H6: 8 | I6: 426039 | J6: 0 | K6: 426039 | L6: 264144.18 | M6: 161894.82 | N6: 166344.46
A7: 46023 | B7: TX-102309 | C7: LBLA-01 | D7: Lavarropas Automático | E7: Línea Blanca | F7: 01-Ene | G7: T1 | H7: 1 | I7: 289599 | J7: 0 | K7: 289599 | L7: 208511.28 | M7: 81087.72 | N7: 149773.77
A8: 46023 | B8: TX-102358 | C8: TECN-01 | D8: Celular Smartphone | E8: Tecnología | F8: 01-Ene | G8: T1 | H8: 2 | I8: 309965 | J8: 0 | K8: 309965 | L8: 235573.4 | M8: 74391.6 | N8: 149162.21
A9: 46023 | B9: TX-102417 | C9: TECN-01 | D9: Celular Smartphone | E9: Tecnología | F9: 01-Ene | G9: T1 | H9: 5 | I9: 519345 | J9: 20773.8 | K9: 498571.2 | L9: 378914.11 | M9: 119657.09 | N9: 149162.21
A10: 46023 | B10: TX-102427 | C10: HOGA-01 | D10: Cafetera Express | E10: Hogar | F10: 01-Ene | G10: T1 | H10: 1 | I10: 767962 | J10: 107514.68 | K10: 660447.32 | L10: 409477.34 | M10: 250969.98 | N10: 166344.46
A11: 46023 | B11: TX-102474 | C11: ELEC-02 | D11: Microondas 20L | E11: Electrónica | F11: 01-Ene | G11: T1 | H11: 2 | I11: 543276 | J11: 76058.64 | K11: 467217.36 | L11: 327052.15 | M11: 140165.21 | N11: 57412.8
A12: 46023 | B12: TX-102840 | C12: ELEC-02 | D12: Microondas 20L | E12: Electrónica | F12: 01-Ene | G12: T1 | H12: 8 | I12: 266017 | J12: 15961.02 | K12: 250055.98 | L12: 175039.19 | M12: 75016.79 | N12: 57412.8
A13: 46023 | B13: TX-102881 | C13: ELEC-01 | D13: TV Smart 55 | E13: Electrónica | F13: 01-Ene | G13: T1 | H13: 10 | I13: 233861 | J13: 16370.27 | K13: 217490.73 | L13: 152243.51 | M13: 65247.22 | N13: 57412.8
... A22000: 46387 | B22000: TX-121940 | C22000: TECN-02 | D22000: Notebook Pro | E22000: Tecnología | F22000: 12-Dic | G22000: T4 | H22000: 6 | I22000: 99871 | J22000: 3994.84 | K22000: 95876.16 | L22000: 72865.88 | M22000: 23010.28 | N22000: 195956.26

Sheet Metas
A1: Mes_Num | B1: Anio | C1: Categoria | D1: Meta_Margen | E1: Nota
A2: 1 | B2: 2026 | C2: Línea Blanca | D2: 66799102
A3: 1 | B3: 2026 | C3: Electrónica | D3: 27845208 | E3: Categoría vacía en el origen: se completó como Electrónica (es la que falta en el mes 1).
A4: 1 | B4: 2026 | C4: Tecnología | D4: 71299536
A5: 1 | B5: 2026 | C5: Hogar | D5: 79678994
A6: 2 | B6: 2026 | C6: Electrónica | D6: 16265653
A7: 2 | B7: 2026 | C7: Línea Blanca | D7: 58878596
A8: 2 | B8: 2026 | C8: Tecnología | D8: 38211684
A9: 2 | B9: 2026 | C9: Hogar | D9: 39845368
A10: 3 | B10: 2026 | C10: Electrónica | D10: 36440778
A11: 3 | B11: 2026 | C11: Línea Blanca | D11: 22093499
A12: 3 | B12: 2026 | C12: Tecnología | D12: 75324155
A13: 3 | B13: 2026 | C13: Hogar | D13: 40653154
A14: 4 | B14: 2026 | C14: Electrónica | D14: 34575269
A15: 4 | B15: 2026 | C15: Línea Blanca | D15: 52847661
... A49: 12 | B49: 2026 | C49: Hogar | D49: 30075812
A51: La meta de cada mes y categoría se reparte en partes iguales entre sus transacciones (columna Meta_Margen_Asignada de Datos), así la meta responde a los mismos segmentadores que las ventas.

Sheet Analisis_IA
C2: Análisis asistido por IA · registro de validación de insights
B4: Flujo usado: 1) análisis humano · 2) ampliación con IA (abogado del diablo) · 3) refinamiento del dashboard
C5: Primero escribí mis conclusiones mirando el dashboard. Después le pedí a la IA que las cuestione (no que lea el gráfico por mí) y con sus objeciones ajusté el diseño y agregué notas.
B6: 1. Mis 3 conclusiones (análisis humano)
C7: 1. El margen total supera la meta, pero no de forma pareja.
C8: En el año el margen estimado llega al 111 % de la meta de margen. Electrónica (156 %) y Hogar (155 %) compensan a Línea Blanca (97 %) y sobre todo a Tecnología (69 %).
C9: 2. Vender más no significa ganar más.
C10: Tecnología es la categoría que más vende ($ 2.371 M, 25,6 % del total) pero la de menor margen (24 %). Hogar vende casi lo mismo y deja 38 % de margen.
C11: 3. Las ventas son estables y los meses bajo meta se explican por la meta, no por las ventas.
C12: Las ventas trimestrales van de $ 2.271 M (T1) a $ 2.335 M (T4), +2,8 %. Enero, mayo y julio quedan bajo la meta aunque julio es el mes de mayor venta: en esos meses la meta fijada es más alta.
B13: 2. Prompts usados
C14: Prompt 1 · Contexto
C15: Soy analista de una empresa ficticia de retail de electrodomésticos en Argentina. Armé un dashboard en Excel con las ventas 2026 (21.999 transacciones, 4 categorías y 8 productos) y lo comparo contra una meta mensual de margen por categoría. El costo de cada venta lo estimé con un porcentaje fijo por categoría (Electrónica 70 %, Línea Blanca 72 %, Tecnología 76 %, Hogar 62 %). Los importes están en pesos nominales.
C16: Prompt 2 · Abogado del diablo
C17: Actuá como abogado del diablo. Estas son mis 3 conclusiones: (1) el margen total supera la meta (111 %) pero Tecnología queda al 69 % y Línea Blanca al 97 %; (2) Tecnología es la que más vende pero la de menor margen; (3) las ventas son estables entre trimestres (+2,8 % de T1 a T4) y los meses bajo meta se explican por metas más altas. No me des la razón: buscá sesgos, errores de lógica, variables omitidas y explicaciones alternativas para cada conclusión, y decime qué dato necesitaría para confirmarla o descartarla.
B18: 3. Respuesta de ChatGPT (resumen)
C19: Le pasé a ChatGPT el contexto del dashboard y mis 3 conclusiones con el pedido de que actúe como abogado del diablo. Este es el resumen de su respuesta.
C20: Problema principal:
C21: el dashboard muestra un margen estimado sobre ventas nominales, no un margen real. Como el costo es un porcentaje fijo por categoría, el ranking de margen % está predeterminado por los supuestos. El dashboard no queda invalidado, pero hay que presentarlo como un modelo de estimación.
C22: Conclusión 1 (margen 111 % de la meta):
C23: el resultado puede ocultar un efecto de mix entre categorías y meses, depende del costo estimado y está impulsado por Hogar, que tiene el costo supuesto más bajo. La inflación también puede distorsionar la comparación contra la meta. Faltaría: meta en % por categoría y mes, costo real por producto y una comparación ponderada.
C24: Conclusión 2 (Tecnología vende más pero gana menos):
C25: confunde margen porcentual con rentabilidad. Una categoría con menor margen % puede aportar tanto o más margen en pesos por volumen, y puede ser una estrategia comercial para generar tráfico. Además, el 24 % de margen de Tecnología no se descubre en los datos: sale del supuesto de 76 % de costo. Faltaría: unidades, margen en pesos y margen por producto, costos reales y descuentos.
C26: Conclusión 3 (ventas estables y meses bajo meta):
C27: comparar solo T1 contra T4 no prueba estabilidad, y decir que los meses quedan bajo meta 'por metas más altas' es una afirmación causal que el dashboard no demuestra. Faltaría, para cada mes: ventas, unidades, ticket promedio, margen, meta, cumplimiento, descuentos y quiebres de stock.
C28: Sugerencia:
C29: mirar también el margen de contribución en pesos por categoría, y leer en conjunto ventas, unidades, ticket promedio, margen %, margen $ y cumplimiento de meta.
C30: Conclusiones reformuladas a partir de la respuesta
... C34: • Meses bajo meta por metas más altas → riesgo: Afirmación causal no demostrada. Versión defendible: Los meses de menor cumplimiento coinciden con metas más elevadas; falta determinar si la causa es la meta, el desempeño comercial u otros factores.
B35: 4. Cambios aplicados al dashboard
C36: • Se agregó la tarjeta 'Cumplimiento de meta' con formato condicional (verde si llega a la meta, rojo si no).
C37: • Se agregó el gráfico de cascada para mostrar dónde se va el dinero entre la venta bruta y el margen.
C38: • El gráfico por categoría compara margen contra meta (no solo ventas), para que se vea que Tecnología vende más pero gana menos.
C39: • Los títulos de los gráficos y el subtítulo cambian con los segmentadores y cuentan la conclusión en vez de describir el gráfico.
C40: • Se agregó al pie del dashboard la advertencia: costos estimados por categoría y valores nominales sin ajustar por inflación.
C41: • Como no hay año anterior, la tarjeta de crecimiento compara 2º semestre contra 1º semestre en lugar de YoY.
C42: • Las notas de análisis del dashboard se reemplazaron por las conclusiones reformuladas y el título del gráfico mensual dejó de afirmar 'ventas estables'.
